Workbook

Sheet Sheet1
B1: Division | C1: Conference Ranking | D1: School | E1: School Tier | F1: Coach | G1: Total Tenure | H1: Current Tenure | I1: Current Team Wins | J1: Current Team Losses | K1: Total Wins | L1: Total Losses | M1: T25 Wins | N1: T25 Losses | O1: T25 Total Games | P1: # Conference Championship Appearances | Q1: # Conference Championship Wins | R1: # Playoff Appearances | S1: # National Championship Appearances | T1: # National Championships | U1: # Bowl Game Appearances | V1: # Bowl Game Wins | W1: Major Coaching Awards | X1: # of Top 20 Recruiting Classes | Y1: # of Top 20 Transfer Classes | Z1: Record in One Score Games?? | AA1: # of Undefeated Szn??? | AC1: Current Win % | AD1: Adj Win % Based on School Prestige | AE1: Adj Win % Based on Tenure | AF1: Adj Win % based on Conference Ranking | AG1: Total Win % | AH1: T25 win % | AI1: Adjusted T25 Win % | AJ1: T25 Games/Total Games (Record Strength) | AK1: Conference Champ Apps/yr | AL1: Bowl Win % | AM1: Bowl Appearances per Season | AN1: Awards/year | AO1: T25 Wins/ Total Wins | AP1: Weighted Score | AU1: References
B2: ACC | C2: 2 | D2: UNC | E2: 3 | F2: Belichick, Bill | G2: 1 | H2: 1 | I2: 0 | J2: 0 | K2: 0 | L2: 0 | M2: 0 | N2: 0 | O2: =N2+M2 -> 0 | P2: 0 | Q2: 0 | R2: 0 | S2: 0 | T2: 0 | U2: 0 | V2: 0 | W2: 0 | AC2: =I2/(SUM(I2:J2)) -> #DIV/0! | AD2: =IF($E2=1,AC2-0.1436,IF($E2=2,AC2-0.0718,IF($E2 = 3,AC2,IF($E2=4,AC2+0.0718, IF($E2=5,AC2+0.1436))))) -> #DIV/0! | AE2: =AD2+(0.0129*H2) -> #DIV/0! | AF2: =IF(C2=1,AE2-0.0145,IF(C2=2,AE2,IF(C2=3,AE2+0.0145))) -> #DIV/0! | AG2: =K2/(SUM(K2:L2)) -> #DIV/0! | AH2: =M2/(SUM(M2:N2)) -> #DIV/0! | AI2: =AH2+(0.0132*M2) -> #DIV/0! | AJ2: =SUM(M2:N2)/SUM(K2:L2) -> #DIV/0! | AK2: =P2/G2 -> 0 | AL2: =V2/U2 -> #DIV/0! | AM2: =U2/G2 -> 0 | AN2: =W2/G2 -> 0 | AO2: =M2/K2 -> #DIV/0! | AP2: =(AF2*Sheet2!$B$2)+(AG2*Sheet2!$B$3)+(AI2*Sheet2!$B$4)+(AJ2*Sheet2!$B$5)+(AK2*Sheet2!$B$6)+(AM2*Sheet2!$B$7)+(AN2*Sheet2!$B$8) -> #DIV/0!
B3: G5 | C3: 3 | D3: Texas State | E3: 5 | F3: GJ Kinne | G3: 3 | H3: 3 | I3: 16 | J3: 10 | K3: 16 | L3: 10 | M3: 0 | N3: 0 | O3: =N3+M3 -> 0 | P3: 0 | Q3: 0 | R3: 0 | S3: 0 | T3: 0 | U3: 2 | V3: 2 | W3: 0 | AC3: =I3/(SUM(I3:J3)) -> 0.61538462 | AD3: =IF($E3=1,AC3-0.1436,IF($E3=2,AC3-0.0718,IF($E3 = 3,AC3,IF($E3=4,AC3+0.0718, IF($E3=5,AC3+0.1436))))) -> 0.75898462 | AE3: =AD3+(0.0129*H3) -> 0.79768462 | AF3: =IF(C3=1,AE3-0.0145,IF(C3=2,AE3,IF(C3=3,AE3+0.0145))) -> 0.81218462 | AG3: =K3/(SUM(K3:L3)) -> 0.61538462 | AH3: =M3/(SUM(M3:N3)) -> #DIV/0! | AI3: =AH3+(0.0132*M3) -> #DIV/0! | AJ3: =SUM(M3:N3)/SUM(K3:L3) -> 0 | AK3: =P3/G3 -> 0 | AL3: =V3/U3 -> 1 | AM3: =U3/G3 -> 0.66666667 | AN3: =W3/G3 -> 0 | AO3: =M3/K3 -> 0 | AP3: =(AF3*Sheet2!$B$2)+(AG3*Sheet2!$B$3)+(AI3*Sheet2!$B$4)+(AJ3*Sheet2!$B$5)+(AK3*Sheet2!$B$6)+(AM3*Sheet2!$B$7)+(AN3*Sheet2!$B$8) -> #DIV/0!
B4: ACC | C4: 2 | D4: Wake Forest | E4: 4 | F4: Dickert, Jake | G4: 5 | H4: 1 | I4: 0 | J4: 0 | K4: 23 | L4: 20 | M4: 3 | N4: 8 | O4: =N4+M4 -> 11 | P4: 0 | Q4: 0 | R4: 0 | S4: 0 | T4: 0 | U4: 3 | V4: 0 | W4: 0 | AC4: =I4/(SUM(I4:J4)) -> #DIV/0! | AD4: =IF($E4=1,AC4-0.1436,IF($E4=2,AC4-0.0718,IF($E4 = 3,AC4,IF($E4=4,AC4+0.0718, IF($E4=5,AC4+0.1436))))) -> #DIV/0! | AE4: =AD4+(0.0129*H4) -> #DIV/0! | AF4: =IF(C4=1,AE4-0.0145,IF(C4=2,AE4,IF(C4=3,AE4+0.0145))) -> #DIV/0! | AG4: =K4/(SUM(K4:L4)) -> 0.53488372 | AH4: =M4/(SUM(M4:N4)) -> 0.27272727 | AI4: =AH4+(0.0132*M4) -> 0.31232727 | AJ4: =SUM(M4:N4)/SUM(K4:L4) -> 0.25581395 | AK4: =P4/G4 -> 0 | AL4: =V4/U4 -> 0 | AM4: =U4/G4 -> 0.6 | AN4: =W4/G4 -> 0 | AO4: =M4/K4 -> 0.13043478 | AP4: =(AF4*Sheet2!$B$2)+(AG4*Sheet2!$B$3)+(AI4*Sheet2!$B$4)+(AJ4*Sheet2!$B$5)+(AK4*Sheet2!$B$6)+(AM4*Sheet2!$B$7)+(AN4*Sheet2!$B$8) -> #DIV/0!
B5: G5 | C5: 3 | D5: UNLV | E5: 4 | F5: Dan Mullen | G5: 14 | H5: 1 | I5: 0 | J5: 0 | K5: 103 | L5: 61 | M5: 7 | N5: 42 | O5: =N5+M5 -> 49 | P5: 1 | Q5: 0 | R5: 0 | S5: 0 | T5: 0 | U5: 10 | V5: 7 | W5: 2 | AC5: =I5/(SUM(I5:J5)) -> #DIV/0! | AD5: =IF($E5=1,AC5-0.1436,IF($E5=2,AC5-0.0718,IF($E5 = 3,AC5,IF($E5=4,AC5+0.0718, IF($E5=5,AC5+0.1436))))) -> #DIV/0! | AE5: =AD5+(0.0129*H5) -> #DIV/0! | AF5: =IF(C5=1,AE5-0.0145,IF(C5=2,AE5,IF(C5=3,AE5+0.0145))) -> #DIV/0! | AG5: =K5/(SUM(K5:L5)) -> 0.62804878 | AH5: =M5/(SUM(M5:N5)) -> 0.14285714 | AI5: =AH5+(0.0132*M5) -> 0.23525714 | AJ5: =SUM(M5:N5)/SUM(K5:L5) -> 0.29878049 | AK5: =P5/G5 -> 0.071428571 | AL5: =V5/U5 -> 0.7 | AM5: =U5/G5 -> 0.71428571 | AN5: =W5/G5 -> 0.14285714 | AO5: =M5/K5 -> 0.067961165 | AP5: =(AF5*Sheet2!$B$2)+(AG5*Sheet2!$B$3)+(AI5*Sheet2!$B$4)+(AJ5*Sheet2!$B$5)+(AK5*Sheet2!$B$6)+(AM5*Sheet2!$B$7)+(AN5*Sheet2!$B$8) -> #DIV/0!
B6: B12 | C6: 2 | D6: UCF | E6: 3 | F6: Scott Frost | G6: 8 | H6: 1 | I6: 0 | J6: 0 | K6: 35 | L6: 38 | M6: 2 | N6: 15 | O6: =N6+M6 -> 17 | P6: 1 | Q6: 1 | R6: 0 | S6: 0 | T6: 0 | U6: 2 | V6: 1 | W6: 2 | X6: 3 | Y6: 2 | AA6: 1 | AC6: =I6/(SUM(I6:J6)) -> #DIV/0! | AD6: =IF($E6=1,AC6-0.1436,IF($E6=2,AC6-0.0718,IF($E6 = 3,AC6,IF($E6=4,AC6+0.0718, IF($E6=5,AC6+0.1436))))) -> #DIV/0! | AE6: =AD6+(0.0129*H6) -> #DIV/0! | AF6: =IF(C6=1,AE6-0.0145,IF(C6=2,AE6,IF(C6=3,AE6+0.0145))) -> #DIV/0! | AG6: =K6/(SUM(K6:L6)) -> 0.47945205 | AH6: =M6/(SUM(M6:N6)) -> 0.11764706 | AI6: =AH6+(0.0132*M6) -> 0.14404706 | AJ6: =SUM(M6:N6)/SUM(K6:L6) -> 0.23287671 | AK6: =P6/G6 -> 0.125 | AL6: =V6/U6 -> 0.5 | AM6: =U6/G6 -> 0.25 | AN6: =W6/G6 -> 0.25 | AO6: =M6/K6 -> 0.057142857 | AP6: =(AF6*Sheet2!$B$2)+(AG6*Sheet2!$B$3)+(AI6*Sheet2!$B$4)+(AJ6*Sheet2!$B$5)+(AK6*Sheet2!$B$6)+(AM6*Sheet2!$B$7)+(AN6*Sheet2!$B$8) -> #DIV/0!
B7: BIG10 | C7: 1 | D7: Purdue | E7: 4 | F7: Barry Odom | G7: 7 | H7: 1 | I7: 0 | J7: 0 | K7: 44 | L7: 33 | M7: 1 | N7: 13 | O7: =N7+M7 -> 14 | P7: 2 | Q7: 0 | R7: 0 | S7: 0 | T7: 0 | U7: 3 | V7: 0 | W7: 1 | AC7: =I7/(SUM(I7:J7)) -> #DIV/0! | AD7: =IF($E7=1,AC7-0.1436,IF($E7=2,AC7-0.0718,IF($E7 = 3,AC7,IF($E7=4,AC7+0.0718, IF($E7=5,AC7+0.1436))))) -> #DIV/0! | AE7: =AD7+(0.0129*H7) -> #DIV/0! | AF7: =IF(C7=1,AE7-0.0145,IF(C7=2,AE7,IF(C7=3,AE7+0.0145))) -> #DIV/0! | AG7: =K7/(SUM(K7:L7)) -> 0.57142857 | AH7: =M7/(SUM(M7:N7)) -> 0.071428571 | AI7: =AH7+(0.0132*M7) -> 0.084628571 | AJ7: =SUM(M7:N7)/SUM(K7:L7) -> 0.18181818 | AK7: =P7/G7 -> 0.28571429 | AL7: =V7/U7 -> 0 | AM7: =U7/G7 -> 0.42857143 | AN7: =W7/G7 -> 0.14285714 | AO7: =M7/K7 -> 0.022727273 | AP7: =(AF7*Sheet2!$B$2)+(AG7*Sheet2!$B$3)+(AI7*Sheet2!$B$4)+(AJ7*Sheet2!$B$5)+(AK7*Sheet2!$B$6)+(AM7*Sheet2!$B$7)+(AN7*Sheet2!$B$8) -> #DIV/0!
A8: 1 | B8: ACC | C8: 2 | D8: Clemson | E8: 1 | F8: Swinney, Dabo | G8: 18 | H8: 18 | I8: 180 | J8: 47 | K8: 180 | L8: 47 | M8: 40 | N8: 16 | O8: =N8+M8 -> 56 | P8: 11 | Q8: 9 | R8: 5 | S8: 4 | T8: 2 | U8: 21 | V8: 12 | W8: 13 | AC8: =I8/(SUM(I8:J8)) -> 0.79295154 | AD8: =IF($E8=1,AC8-0.1436,IF($E8=2,AC8-0.0718,IF($E8 = 3,AC8,IF($E8=4,AC8+0.0718, IF($E8=5,AC8+0.1436))))) -> 0.64935154 | AE8: =AD8+(0.0129*H8) -> 0.88155154 | AF8: =IF(C8=1,AE8-0.0145,IF(C8=2,AE8,IF(C8=3,AE8+0.0145))) -> 0.88155154 | AG8: =K8/(SUM(K8:L8)) -> 0.79295154 | AH8: =M8/(SUM(M8:N8)) -> 0.71428571 | AI8: =AH8+(0.0132*M8) -> 1.2422857 | AJ8: =SUM(M8:N8)/SUM(K8:L8) -> 0.24669604 | AK8: =P8/G8 -> 0.61111111 | AL8: =V8/U8 -> 0.57142857 | AM8: =U8/G8 -> 1.1666667 | AN8: =W8/G8 -> 0.72222222 | AO8: =M8/K8 -> 0.22222222 | AP8: =(AF8*Sheet2!$B$2)+(AG8*Sheet2!$B$3)+(AI8*Sheet2!$B$4)+(AJ8*Sheet2!$B$5)+(AK8*Sheet2!$B$6)+(AM8*Sheet2!$B$7)+(AN8*Sheet2!$B$8) -> 82.992041
A9: 2 | B9: SEC | C9: 1 | D9: Georgia | E9: 1 | F9: Kirby Smart | G9: 10 | H9: 10 | I9: 105 | J9: 19 | K9: 105 | L9: 19 | M9: 28 | N9: 11 | O9: =N9+M9 -> 39 | P9: 7 | Q9: 4 | R9: 4 | S9: 3 | T9: 2 | U9: 12 | V9: 9 | W9: 6 | AC9: =I9/(SUM(I9:J9)) -> 0.84677419 | AD9: =IF($E9=1,AC9-0.1436,IF($E9=2,AC9-0.0718,IF($E9 = 3,AC9,IF($E9=4,AC9+0.0718, IF($E9=5,AC9+0.1436))))) -> 0.70317419 | AE9: =AD9+(0.0129*H9) -> 0.83217419 | AF9: =IF(C9=1,AE9-0.0145,IF(C9=2,AE9,IF(C9=3,AE9+0.0145))) -> 0.81767419 | AG9: =K9/(SUM(K9:L9)) -> 0.84677419 | AH9: =M9/(SUM(M9:N9)) -> 0.71794872 | AI9: =AH9+(0.0132*M9) -> 1.0875487 | AJ9: =SUM(M9:N9)/SUM(K9:L9) -> 0.31451613 | AK9: =P9/G9 -> 0.7 | AL9: =V9/U9 -> 0.75 | AM9: =U9/G9 -> 1.2 | AN9: =W9/G9 -> 0.6 | AO9: =M9/K9 -> 0.26666667 | AP9: =(AF9*Sheet2!$B$2)+(AG9*Sheet2!$B$3)+(AI9*Sheet2!$B$4)+(AJ9*Sheet2!$B$5)+(AK9*Sheet2!$B$6)+(AM9*Sheet2!$B$7)+(AN9*Sheet2!$B$8) -> 81.574729
A10: 3 | B10: BIG10 | C10: 1 | D10: OSU | E10: 1 | F10: Ryan Day | G10: 8 | H10: 8 | I10: 70 | J10: 10 | K10: 70 | L10: 10 | M10: 24 | N10: 9 | O10: =N10+M10 -> 33 | P10: 2 | Q10: 2 | R10: 4 | S10: 1 | T10: 1 | U10: 10 | V10: 6 | W10: 1 | AC10: =I10/(SUM(I10:J10)) -> 0.875 | AD10: =IF($E10=1,AC10-0.1436,IF($E10=2,AC10-0.0718,IF($E10 = 3,AC10,IF($E10=4,AC10+0.0718, IF($E10=5,AC10+0.1436))))) -> 0.7314 | AE10: =AD10+(0.0129*H10) -> 0.8346 | AF10: =IF(C10=1,AE10-0.0145,IF(C10=2,AE10,IF(C10=3,AE10+0.0145))) -> 0.8201 | AG10: =K10/(SUM(K10:L10)) -> 0.875 | AH10: =M10/(SUM(M10:N10)) -> 0.72727273 | AI10: =AH10+(0.0132*M10) -> 1.0440727 | AJ10: =SUM(M10:N10)/SUM(K10:L10) -> 0.4125 | AK10: =P10/G10 -> 0.25 | AL10: =V10/U10 -> 0.6 | AM10: =U10/G10 -> 1.25 | AN10: =W10/G10 -> 0.125 | AO10: =M10/K10 -> 0.34285714 | AP10: =(AF10*Sheet2!$B$2)+(AG10*Sheet2!$B$3)+(AI10*Sheet2!$B$4)+(AJ10*Sheet2!$B$5)+(AK10*Sheet2!$B$6)+(AM10*Sheet2!$B$7)+(AN10*Sheet2!$B$8) -> 76.394227
A11: 4 | B11: G5 | C11: 3 | D11: Boise State | E11: 3 | F11: Spencer Danielson | G11: 2.5 | H11: 2.5 | I11: 15 | J11: 3 | K11: 15 | L11: 3 | M11: 1 | N11: 2 | O11: =N11+M11 -> 3 | P11: 2 | Q11: 2 | R11: 1 | S11: 0 | T11: 0 | U11: 2 | V11: 0 | W11: 1 | AC11: =I11/(SUM(I11:J11)) -> 0.83333333 | AD11: =IF($E11=1,AC11-0.1436,IF($E11=2,AC11-0.0718,IF($E11 = 3,AC11,IF($E11=4,AC11+0.0718, IF($E11=5,AC11+0.1436))))) -> 0.83333333 | AE11: =AD11+(0.0129*H11) -> 0.86558333 | AF11: =IF(C11=1,AE11-0.0145,IF(C11=2,AE11,IF(C11=3,AE11+0.0145))) -> 0.88008333 | AG11: =K11/(SUM(K11:L11)) -> 0.83333333 | AH11: =M11/(SUM(M11:N11)) -> 0.33333333 | AI11: =AH11+(0.0132*M11) -> 0.34653333 | AJ11: =SUM(M11:N11)/SUM(K11:L11) -> 0.16666667 | AK11: =P11/G11 -> 0.8 | AL11: =V11/U11 -> 0 | AM11: =U11/G11 -> 0.8 | AN11: =W11/G11 -> 0.4 | AO11: =M11/K11 -> 0.066666667 | AP11: =(AF11*Sheet2!$B$2)+(AG11*Sheet2!$B$3)+(AI11*Sheet2!$B$4)+(AJ11*Sheet2!$B$5)+(AK11*Sheet2!$B$6)+(AM11*Sheet2!$B$7)+(AN11*Sheet2!$B$8) -> 70.601583
A12: 5 | B12: B12 | C12: 2 | D12: Oklahoma State | E12: 2 | F12: Mike Gundy | G12: 20 | H12: 20 | I12: 169 | J12: 88 | K12: 169 | L12: 88 | M12: 39 | N12: 46 | O12: =N12+M12 -> 85 | P12: 3 | Q12: 1 | R12: 0 | S12: 0 | T12: 0 | U12: 18 | V12: 12 | W12: 4 | X12: 0 | Y12: 0 | AC12: =I12/(SUM(I12:J12)) -> 0.65758755 | AD12: =IF($E12=1,AC12-0.1436,IF($E12=2,AC12-0.0718,IF($E12 = 3,AC12,IF($E12=4,AC12+0.0718, IF($E12=5,AC12+0.1436))))) -> 0.58578755 | AE12: =AD12+(0.0129*H12) -> 0.84378755 | AF12: =IF(C12=1,AE12-0.0145,IF(C12=2,AE12,IF(C12=3,AE12+0.0145))) -> 0.84378755 | AG12: =K12/(SUM(K12:L12)) -> 0.65758755 | AH12: =M12/(SUM(M12:N12)) -> 0.45882353 | AI12: =AH12+(0.0132*M12) -> 0.97362353 | AJ12: =SUM(M12:N12)/SUM(K12:L12) -> 0.3307393 | AK12: =P12/G12 -> 0.15 | AL12: =V12/U12 -> 0.66666667 | AM12: =U12/G12 -> 0.9 | AN12: =W12/G12 -> 0.2 | AO12: =M12/K12 -> 0.23076923 | AP12: =(AF12*Sheet2!$B$2)+(AG12*Sheet2!$B$3)+(AI12*Sheet2!$B$4)+(AJ12*Sheet2!$B$5)+(AK12*Sheet2!$B$6)+(AM12*Sheet2!$B$7)+(AN12*Sheet2!$B$8) -> 67.227943
A13: 6 | B13: BIG10 | C13: 1 | D13: Oregon | E13: 1 | F13: Dan Lanning | G13: 4 | H13: 4 | I13: 35 | J13: 6 | K13: 35 | L13: 6 | M13: 10 | N13: 6 | O13: =N13+M13 -> 16 | P13: 2 | Q13: 1 | R13: 1 | S13: 0 | T13: 0 | U13: 3 | V13: 2 | W13: 0 | AC13: =I13/(SUM(I13:J13)) -> 0.85365854 | AD13: =IF($E13=1,AC13-0.1436,IF($E13=2,AC13-0.0718,IF($E13 = 3,AC13,IF($E13=4,AC13+0.0718, IF($E13=5,AC13+0.1436))))) -> 0.71005854 | AE13: =AD13+(0.0129*H13) -> 0.76165854 | AF13: =IF(C13=1,AE13-0.0145,IF(C13=2,AE13,IF(C13=3,AE13+0.0145))) -> 0.74715854 | AG13: =K13/(SUM(K13:L13)) -> 0.85365854 | AH13: =M13/(SUM(M13:N13)) -> 0.625 | AI13: =AH13+(0.0132*M13) -> 0.757 | AJ13: =SUM(M13:N13)/SUM(K13:L13) -> 0.3902439 | AK13: =P13/G13 -> 0.5 | AL13: =V13/U13 -> 0.66666667 | AM13: =U13/G13 -> 0.75 | AN13: =W13/G13 -> 0 | AO13: =M13/K13 -> 0.28571429 | AP13: =(AF13*Sheet2!$B$2)+(AG13*Sheet2!$B$3)+(AI13*Sheet2!$B$4)+(AJ13*Sheet2!$B$5)+(AK13*Sheet2!$B$6)+(AM13*Sheet2!$B$7)+(AN13*Sheet2!$B$8) -> 67.196159
A14: 7 | B14: B12 | C14: 2 | D14: Utah | E14: 3 | F14: Kyle Whittingham | G14: 21 | H14: 21 | I14: 167 | J14: 86 | K14: 167 | L14: 86 | M14: 23 | N14: 36 | O14: =N14+M14 -> 59 | P14: 3 | Q14: 3 | R14: 0 | S14: 0 | T14: 0 | U14: 17 | V14: 11 | W14: 3 | AC14: =I14/(SUM(I14:J14)) -> 0.66007905 | AD14: =IF($E14=1,AC14-0.1436,IF($E14=2,AC14-0.0718,IF($E14 = 3,AC14,IF($E14=4,AC14+0.0718, IF($E14=5,AC14+0.1436))))) -> 0.66007905 | AE14: =AD14+(0.0129*H14) -> 0.93097905 | AF14: =IF(C14=1,AE14-0.0145,IF(C14=2,AE14,IF(C14=3,AE14+0.0145))) -> 0.93097905 | AG14: =K14/(SUM(K14:L14)) -> 0.66007905 | AH14: =M14/(SUM(M14:N14)) -> 0.38983051 | AI14: =AH14+(0.0132*M14) -> 0.69343051 | AJ14: =SUM(M14:N14)/SUM(K14:L14) -> 0.23320158 | AK14: =P14/G14 -> 0.14285714 | AL14: =V14/U14 -> 0.64705882 | AM14: =U14/G14 -> 0.80952381 | AN14: =W14/G14 -> 0.14285714 | AO14: =M14/K14 -> 0.13772455 | AP14: =(AF14*Sheet2!$B$2)+(AG14*Sheet2!$B$3)+(AI14*Sheet2!$B$4)+(AJ14*Sheet2!$B$5)+(AK14*Sheet2!$B$6)+(AM14*Sheet2!$B$7)+(AN14*Sheet2!$B$8) -> 65.290264
A15: 8 | B15: BIG10 | C15: 1 | D15: Indiana | E15: 3 | F15: Curt Cignetti | G15: 4 | H15: 2 | I15: 11 | J15: 2 | K15: 30 | L15: 6 | M15: 2 | N15: 2 | O15: =N15+M15 -> 4 | P15: 2 | Q15: 0 | R15: 1 | S15: 0 | T15: 0 | U15: 1 | V15: 0 | W15: 3 | AC15: =I15/(SUM(I15:J15)) -> 0.84615385 | AD15: =IF($E15=1,AC15-0.1436,IF($E15=2,AC15-0.0718,IF($E15 = 3,AC15,IF($E15=4,AC15+0.0718, IF($E15=5,AC15+0.1436))))) -> 0.84615385 | AE15: =AD15+(0.0129*H15) -> 0.87195385 | AF15: =IF(C15=1,AE15-0.0145,IF(C15=2,AE15,IF(C15=3,AE15+0.0145))) -> 0.85745385 | AG15: =K15/(SUM(K15:L15)) -> 0.83333333 | AH15: =M15/(SUM(M15:N15)) -> 0.5 | AI15: =AH15+(0.0132*M15) -> 0.5264 | AJ15: =SUM(M15:N15)/SUM(K15:L15) -> 0.11111111 | AK15: =P15/G15 -> 0.5 | AL15: =V15/U15 -> 0 | AM15: =U15/G15 -> 0.25 | AN15: =W15/G15 -> 0.75 | AO15: =M15/K15 -> 0.066666667 | AP15: =(AF15*Sheet2!$B$2)+(AG15*Sheet2!$B$3)+(AI15*Sheet2!$B$4)+(AJ15*Sheet2!$B$5)+(AK15*Sheet2!$B$6)+(AM15*Sheet2!$B$7)+(AN15*Sheet2!$B$8) -> 64.302662
A16: 9 | B16: ACC | C16: 2 | D16: Syracuse | E16: 3 | F16: Brown, Fran | G16: 2 | H16: 2 | I16: 10 | J16: 3 | K16: 10 | L16: 3 | M16: 3 | N16: 1 | O16: =N16+M16 -> 4 | P16: 0 | Q16: 0 | R16: 0 | S16: 0 | T16: 0 | U16: 1 | V16: 1 | W16: 2 | AC16: =I16/(SUM(I16:J16)) -> 0.76923077 | AD16: =IF($E16=1,AC16-0.1436,IF($E16=2,AC16-0.0718,IF($E16 = 3,AC16,IF($E16=4,AC16+0.0718, IF($E16=5,AC16+0.1436))))) -> 0.76923077 | AE16: =AD16+(0.0129*H16) -> 0.79503077 | AF16: =IF(C16=1,AE16-0.0145,IF(C16=2,AE16,IF(C16=3,AE16+0.0145))) -> 0.79503077 | AG16: =K16/(SUM(K16:L16)) -> 0.76923077 | AH16: =M16/(SUM(M16:N16)) -> 0.75 | AI16: =AH16+(0.0132*M16) -> 0.7896 | AJ16: =SUM(M16:N16)/SUM(K16:L16) -> 0.30769231 | AK16: =P16/G16 -> 0 | AL16: =V16/U16 -> 1 | AM16: =U16/G16 -> 0.5 | AN16: =W16/G16 -> 1 | AO16: =M16/K16 -> 0.3 | AP16: =(AF16*Sheet2!$B$2)+(AG16*Sheet2!$B$3)+(AI16*Sheet2!$B$4)+(AJ16*Sheet2!$B$5)+(AK16*Sheet2!$B$6)+(AM16*Sheet2!$B$7)+(AN16*Sheet2!$B$8) -> 64.183615
A17: 10 | B17: BIG10 | C17: 1 | D17: Iowa | E17: 2 | F17: Kirk Ferentz | G17: 29 | H17: 26 | I17: 206 | J17: 124 | K17: 216 | L17: 145 | M17: 33 | N17: 56 | O17: =N17+M17 -> 89 | P17: 3 | Q17: 2 | R17: 0 | S17: 0 | T17: 0 | U17: 21 | V17: 10 | W17: 6 | AC17: =I17/(SUM(I17:J17)) -> 0.62424242 | AD17: =IF($E17=1,AC17-0.1436,IF($E17=2,AC17-0.0718,IF($E17 = 3,AC17,IF($E17=4,AC17+0.0718, IF($E17=5,AC17+0.1436))))) -> 0.55244242 | AE17: =AD17+(0.0129*H17) -> 0.88784242 | AF17: =IF(C17=1,AE17-0.0145,IF(C17=2,AE17,IF(C17=3,AE17+0.0145))) -> 0.87334242 | AG17: =K17/(SUM(K17:L17)) -> 0.59833795 | AH17: =M17/(SUM(M17:N17)) -> 0.37078652 | AI17: =AH17+(0.0132*M17) -> 0.80638652 | AJ17: =SUM(M17:N17)/SUM(K17:L17) -> 0.2465374 | AK17: =P17/G17 -> 0.10344828 | AL17: =V17/U17 -> 0.47619048 | AM17: =U17/G17 -> 0.72413793 | AN17: =W17/G17 -> 0.20689655 | AO17: =M17/K17 -> 0.15277778 | AP17: =(AF17*Sheet2!$B$2)+(AG17*Sheet2!$B$3)+(AI17*Sheet2!$B$4)+(AJ17*Sheet2!$B$5)+(AK17*Sheet2!$B$6)+(AM17*Sheet2!$B$7)+(AN17*Sheet2!$B$8) -> 62.373328
A18: 11 | B18: G5 | C18: 3 | D18: Liberty | E18: 4 | F18: Jamey Chadwell | G18: 8 | H18: 3 | I18: 21 | J18: 5 | K18: 47 | L18: 27 | M18: 1 | N18: 2 | O18: =N18+M18 -> 3 | P18: 5 | Q18: 4 | R18: 0 | S18: 0 | T18: 0 | U18: 4 | V18: 1 | W18: 3 | AC18: =I18/(SUM(I18:J18)) -> 0.80769231 | AD18: =IF($E18=1,AC18-0.1436,IF($E18=2,AC18-0.0718,IF($E18 = 3,AC18,IF($E18=4,AC18+0.0718, IF($E18=5,AC18+0.1436))))) -> 0.87949231 | AE18: =AD18+(0.0129*H18) -> 0.91819231 | AF18: =IF(C18=1,AE18-0.0145,IF(C18=2,AE18,IF(C18=3,AE18+0.0145))) -> 0.93269231 | AG18: =K18/(SUM(K18:L18)) -> 0.63513514 | AH18: =M18/(SUM(M18:N18)) -> 0.33333333 | AI18: =AH18+(0.0132*M18) -> 0.34653333 | AJ18: =SUM(M18:N18)/SUM(K18:L18) -> 0.040540541 | AK18: =P18/G18 -> 0.625 | AL18: =V18/U18 -> 0.25 | AM18: =U18/G18 -> 0.5 | AN18: =W18/G18 -> 0.375 | AO18: =M18/K18 -> 0.021276596 | AP18: =(AF18*Sheet2!$B$2)+(AG18*Sheet2!$B$3)+(AI18*Sheet2!$B$4)+(AJ18*Sheet2!$B$5)+(AK18*Sheet2!$B$6)+(AM18*Sheet2!$B$7)+(AN18*Sheet2!$B$8) -> 62.342672 | AU18: https://247sports.com/longformarticle/college-football-rankings-coaches-with-best-worst-records-against-top-25-teams-233938982/#2447212
A19: 12 | B19: SEC | C19: 1 | D19: Alabama | E19: 1 | F19: Kaelen Debor | G19: 6 | H19: 2 | I19: 9 | J19: 4 | K19: 46 | L19: 13 | M19: 15 | N19: 3 | O19: =N19+M19 -> 18 | P19: 1 | Q19: 1 | R19: 1 | S19: 1 | T19: 0 | U19: 6 | V19: 4 | W19: 2 | AC19: =I19/(SUM(I19:J19)) -> 0.69230769 | AD19: =IF($E19=1,AC19-0.1436,IF($E19=2,AC19-0.0718,IF($E19 = 3,AC19,IF($E19=4,AC19+0.0718, IF($E19=5,AC19+0.1436))))) -> 0.54870769 | AE19: =AD19+(0.0129*H19) -> 0.57450769 | AF19: =IF(C19=1,AE19-0.0145,IF(C19=2,AE19,IF(C19=3,AE19+0.0145))) -> 0.56000769 | AG19: =K19/(SUM(K19:L19)) -> 0.77966102 | AH19: =M19/(SUM(M19:N19)) -> 0.83333333 | AI19: =AH19+(0.0132*M19) -> 1.0313333 | AJ19: =SUM(M19:N19)/SUM(K19:L19) -> 0.30508475 | AK19: =P19/G19 -> 0.16666667 | AL19: =V19/U19 -> 0.66666667 | AM19: =U19/G19 -> 1 | AN19: =W19/G19 -> 0.33333333 | AO19: =M19/K19 -> 0.32608696 | AP19: =(AF19*Sheet2!$B$2)+(AG19*Sheet2!$B$3)+(AI19*Sheet2!$B$4)+(AJ19*Sheet2!$B$5)+(AK19*Sheet2!$B$6)+(AM19*Sheet2!$B$7)+(AN19*Sheet2!$B$8) -> 61.891004 | AU19: https://www.reddit.com/r/CFB/comments/etm9bu/coaches_record_vs_ranked_opponents/
A20: 13 | B20: BIG10 | C20: 1 | D20: USC | E20: 1 | F20: Lincoln Riley | G20: 9 | H20: 4 | I20: 26 | J20: 14 | K20: 81 | L20: 24 | M20: 18 | N20: 15 | O20: =N20+M20 -> 33 | P20: 5 | Q20: 4 | R20: 3 | S20: 0 | T20: 0 | U20: 7 | V20: 3 | W20: 2 | AC20: =I20/(SUM(I20:J20)) -> 0.65 | AD20: =IF($E20=1,AC20-0.1436,IF($E20=2,AC20-0.0718,IF($E20 = 3,AC20,IF($E20=4,AC20+0.0718, IF($E20=5,AC20+0.1436))))) -> 0.5064 | AE20: =AD20+(0.0129*H20) -> 0.558 | AF20: =IF(C20=1,AE20-0.0145,IF(C20=2,AE20,IF(C20=3,AE20+0.0145))) -> 0.5435 | AG20: =K20/(SUM(K20:L20)) -> 0.77142857 | AH20: =M20/(SUM(M20:N20)) -> 0.54545455 | AI20: =AH20+(0.0132*M20) -> 0.78305455 | AJ20: =SUM(M20:N20)/SUM(K20:L20) -> 0.31428571 | AK20: =P20/G20 -> 0.55555556 | AL20: =V20/U20 -> 0.42857143 | AM20: =U20/G20 -> 0.77777778 | AN20: =W20/G20 -> 0.22222222 | AO20: =M20/K20 -> 0.22222222 | AP20: =(AF20*Sheet2!$B$2)+(AG20*Sheet2!$B$3)+(AI20*Sheet2!$B$4)+(AJ20*Sheet2!$B$5)+(AK20*Sheet2!$B$6)+(AM20*Sheet2!$B$7)+(AN20*Sheet2!$B$8) -> 59.868918
A21: 14 | B21: ACC | C21: 2 | D21: SMU | E21: 3 | F21: Lashlee, Rhett | G21: 4 | H21: 4 | I21: 29 | J21: 12 | K21: 29 | L21: 12 | M21: 2 | N21: 5 | O21: =N21+M21 -> 7 | P21: 2 | Q21: 1 | R21: 1 | S21: 0 | T21: 0 | U21: 3 | V21: 0 | W21: 1 | AC21: =I21/(SUM(I21:J21)) -> 0.70731707 | AD21: =IF($E21=1,AC21-0.1436,IF($E21=2,AC21-0.0718,IF($E21 = 3,AC21,IF($E21=4,AC21+0.0718, IF($E21=5,AC21+0.1436))))) -> 0.70731707 | AE21: =AD21+(0.0129*H21) -> 0.75891707 | AF21: =IF(C21=1,AE21-0.0145,IF(C21=2,AE21,IF(C21=3,AE21+0.0145))) -> 0.75891707 | AG21: =K21/(SUM(K21:L21)) -> 0.70731707 | AH21: =M21/(SUM(M21:N21)) -> 0.28571429 | AI21: =AH21+(0.0132*M21) -> 0.31211429 | AJ21: =SUM(M21:N21)/SUM(K21:L21) -> 0.17073171 | AK21: =P21/G21 -> 0.5 | AL21: =V21/U21 -> 0 | AM21: =U21/G21 -> 0.75 | AN21: =W21/G21 -> 0.25 | AO21: =M21/K21 -> 0.068965517 | AP21: =(AF21*Sheet2!$B$2)+(AG21*Sheet2!$B$3)+(AI21*Sheet2!$B$4)+(AJ21*Sheet2!$B$5)+(AK21*Sheet2!$B$6)+(AM21*Sheet2!$B$7)+(AN21*Sheet2!$B$8) -> 59.286899
A22: 15 | B22: SEC | C22: 1 | D22: Tennessee | E22: 2 | F22: Josh Heupel | G22: 8 | H22: 5 | I22: 37 | J22: 15 | K22: 65 | L22: 23 | M22: 11 | N22: 10 | O22: =N22+M22 -> 21 | P22: 1 | Q22: 1 | R22: 1 | S22: 0 | T22: 0 | U22: 7 | V22: 3 | W22: 1 | AC22: =I22/(SUM(I22:J22)) -> 0.71153846 | AD22: =IF($E22=1,AC22-0.1436,IF($E22=2,AC22-0.0718,IF($E22 = 3,AC22,IF($E22=4,AC22+0.0718, IF($E22=5,AC22+0.1436))))) -> 0.63973846 | AE22: =AD22+(0.0129*H22) -> 0.70423846 | AF22: =IF(C22=1,AE22-0.0145,IF(C22=2,AE22,IF(C22=3,AE22+0.0145))) -> 0.68973846 | AG22: =K22/(SUM(K22:L22)) -> 0.73863636 | AH22: =M22/(SUM(M22:N22)) -> 0.52380952 | AI22: =AH22+(0.0132*M22) -> 0.66900952 | AJ22: =SUM(M22:N22)/SUM(K22:L22) -> 0.23863636 | AK22: =P22/G22 -> 0.125 | AL22: =V22/U22 -> 0.42857143 | AM22: =U22/G22 -> 0.875 | AN22: =W22/G22 -> 0.125 | AO22: =M22/K22 -> 0.16923077 | AP22: =(AF22*Sheet2!$B$2)+(AG22*Sheet2!$B$3)+(AI22*Sheet2!$B$4)+(AJ22*Sheet2!$B$5)+(AK22*Sheet2!$B$6)+(AM22*Sheet2!$B$7)+(AN22*Sheet2!$B$8) -> 58.615032
A23: 16 | B23: G5 | C23: 3 | D23: Toledo | E23: 4 | F23: Jason Candle | G23: 11 | H23: 11 | I23: 73 | J23: 40 | K23: 73 | L23: 40 | M23: 2 | N23: 5 | O23: =N23+M23 -> 7 | P23: 3 | Q23: 2 | R23: 0 | S23: 0 | T23: 0 | U23: 8 | V23: 3 | W23: 2 | AC23: =I23/(SUM(I23:J23)) -> 0.6460177 | AD23: =IF($E23=1,AC23-0.1436,IF($E23=2,AC23-0.0718,IF($E23 = 3,AC23,IF($E23=4,AC23+0.0718, IF($E23=5,AC23+0.1436))))) -> 0.7178177 | AE23: =AD23+(0.0129*H23) -> 0.8597177 | AF23: =IF(C23=1,AE23-0.0145,IF(C23=2,AE23,IF(C23=3,AE23+0.0145))) -> 0.8742177 | AG23: =K23/(SUM(K23:L23)) -> 0.6460177 | AH23: =M23/(SUM(M23:N23)) -> 0.28571429 | AI23: =AH23+(0.0132*M23) -> 0.31211429 | AJ23: =SUM(M23:N23)/SUM(K23:L23) -> 0.061946903 | AK23: =P23/G23 -> 0.27272727 | AL23: =V23/U23 -> 0.375 | AM23: =U23/G23 -> 0.72727273 | AN23: =W23/G23 -> 0.18181818 | AO23: =M23/K23 -> 0.02739726 | AP23: =(AF23*Sheet2!$B$2)+(AG23*Sheet2!$B$3)+(AI23*Sheet2!$B$4)+(AJ23*Sheet2!$B$5)+(AK23*Sheet2!$B$6)+(AM23*Sheet2!$B$7)+(AN23*Sheet2!$B$8) -> 58.167676
A24: 17 | B24: G5 | C24: 3 | D24: Tulane | E24: 4 | F24: Jon Sumrall | G24: 4 | H24: 2 | I24: 9 | J24: 5 | K24: 32 | L24: 9 | M24: 0 | N24: 5 | O24: =N24+M24 -> 5 | P24: 3 | Q24: 2 | R24: 0 | S24: 0 | T24: 0 | U24: 2 | V24: 1 | W24: 1 | AC24: =I24/(SUM(I24:J24)) -> 0.64285714 | AD24: =IF($E24=1,AC24-0.1436,IF($E24=2,AC24-0.0718,IF($E24 = 3,AC24,IF($E24=4,AC24+0.0718, IF($E24=5,AC24+0.1436))))) -> 0.71465714 | AE24: =AD24+(0.0129*H24) -> 0.74045714 | AF24: =IF(C24=1,AE24-0.0145,IF(C24=2,AE24,IF(C24=3,AE24+0.0145))) -> 0.75495714 | AG24: =K24/(SUM(K24:L24)) -> 0.7804878 | AH24: =M24/(SUM(M24:N24)) -> 0 | AI24: =AH24+(0.0132*M24) -> 0 | AJ24: =SUM(M24:N24)/SUM(K24:L24) -> 0.12195122 | AK24: =P24/G24 -> 0.75 | AL24: =V24/U24 -> 0.5 | AM24: =U24/G24 -> 0.5 | AN24: =W24/G24 -> 0.25 | AO24: =M24/K24 -> 0 | AP24: =(AF24*Sheet2!$B$2)+(AG24*Sheet2!$B$3)+(AI24*Sheet2!$B$4)+(AJ24*Sheet2!$B$5)+(AK24*Sheet2!$B$6)+(AM24*Sheet2!$B$7)+(AN24*Sheet2!$B$8) -> 57.002768
A25: 18 | B25: BIG10 | C25: 1 | D25: PSU | E25: 1 | F25: James Franklin | G25: 15 | H25: 12 | I25: 101 | J25: 42 | K25: 125 | L25: 57 | M25: 16 | N25: 36 | O25: =N25+M25 -> 52 | P25: 2 | Q25: 1 | R25: 1 | S25: 0 | T25: 0 | U25: 13 | V25: 7 | W25: 1 | AC25: =I25/(SUM(I25:J25)) -> 0.70629371 | AD25: =IF($E25=1,AC25-0.1436,IF($E25=2,AC25-0.0718,IF($E25 = 3,AC25,IF($E25=4,AC25+0.0718, IF($E25=5,AC25+0.1436))))) -> 0.56269371 | AE25: =AD25+(0.0129*H25) -> 0.71749371 | AF25: =IF(C25=1,AE25-0.0145,IF(C25=2,AE25,IF(C25=3,AE25+0.0145))) -> 0.70299371 | AG25: =K25/(SUM(K25:L25)) -> 0.68681319 | AH25: =M25/(SUM(M25:N25)) -> 0.30769231 | AI25: =AH25+(0.0132*M25) -> 0.51889231 | AJ25: =SUM(M25:N25)/SUM(K25:L25) -> 0.28571429 | AK25: =P25/G25 -> 0.13333333 | AL25: =V25/U25 -> 0.53846154 | AM25: =U25/G25 -> 0.86666667 | AN25: =W25/G25 -> 0.066666667 | AO25: =M25/K25 -> 0.128 | AP25: =(AF25*Sheet2!$B$2)+(AG25*Sheet2!$B$3)+(AI25*Sheet2!$B$4)+(AJ25*Sheet2!$B$5)+(AK25*Sheet2!$B$6)+(AM25*Sheet2!$B$7)+(AN25*Sheet2!$B$8) -> 56.720443
A26: 19 | B26: G5 | C26: 3 | D26: UTSA | E26: 3 | F26: Jeff Traylor | G26: 6 | H26: 6 | I26: 46 | J26: 20 | K26: 46 | L26: 20 | M26: 0 | N26: 8 | O26: =N26+M26 -> 8 | P26: 2 | Q26: 2 | R26: 0 | S26: 0 | T26: 0 | U26: 5 | V26: 2 | W26: 2 | AC26: =I26/(SUM(I26:J26)) -> 0.6969697 | AD26: =IF($E26=1,AC26-0.1436,IF($E26=2,AC26-0.0718,IF($E26 = 3,AC26,IF($E26=4,AC26+0.0718, IF($E26=5,AC26+0.1436))))) -> 0.6969697 | AE26: =AD26+(0.0129*H26) -> 0.7743697 | AF26: =IF(C26=1,AE26-0.0145,IF(C26=2,AE26,IF(C26=3,AE26+0.0145))) -> 0.7888697 | AG26: =K26/(SUM(K26:L26)) -> 0.6969697 | AH26: =M26/(SUM(M26:N26)) -> 0 | AI26: =AH26+(0.0132*M26) -> 0 | AJ26: =SUM(M26:N26)/SUM(K26:L26) -> 0.12121212 | AK26: =P26/G26 -> 0.33333333 | AL26: =V26/U26 -> 0.4 | AM26: =U26/G26 -> 0.83333333 | AN26: =W26/G26 -> 0.33333333 | AO26: =M26/K26 -> 0 | AP26: =(AF26*Sheet2!$B$2)+(AG26*Sheet2!$B$3)+(AI26*Sheet2!$B$4)+(AJ26*Sheet2!$B$5)+(AK26*Sheet2!$B$6)+(AM26*Sheet2!$B$7)+(AN26*Sheet2!$B$8) -> 56.095288
A27: 20 | B27: B12 | C27: 2 | D27: WVU | E27: 3 | F27: Rich Rodriguez | G27: 19 | H27: 8 | I27: 86 | J27: 60 | K27: 136 | L27: 92 | M27: 21 | N27: 42 | O27: =N27+M27 -> 63 | P27: 7 | Q27: 6 | R27: 0 | S27: 0 | T27: 0 | U27: 12 | V27: 6 | W27: 4 | AC27: =I27/(SUM(I27:J27)) -> 0.5890411 | AD27: =IF($E27=1,AC27-0.1436,IF($E27=2,AC27-0.0718,IF($E27 = 3,AC27,IF($E27=4,AC27+0.0718, IF($E27=5,AC27+0.1436))))) -> 0.5890411 | AE27: =AD27+(0.0129*H27) -> 0.6922411 | AF27: =IF(C27=1,AE27-0.0145,IF(C27=2,AE27,IF(C27=3,AE27+0.0145))) -> 0.6922411 | AG27: =K27/(SUM(K27:L27)) -> 0.59649123 | AH27: =M27/(SUM(M27:N27)) -> 0.33333333 | AI27: =AH27+(0.0132*M27) -> 0.61053333 | AJ27: =SUM(M27:N27)/SUM(K27:L27) -> 0.27631579 | AK27: =P27/G27 -> 0.36842105 | AL27: =V27/U27 -> 0.5 | AM27: =U27/G27 -> 0.63157895 | AN27: =W27/G27 -> 0.21052632 | AO27: =M27/K27 -> 0.15441176 | AP27: =(AF27*Sheet2!$B$2)+(AG27*Sheet2!$B$3)+(AI27*Sheet2!$B$4)+(AJ27*Sheet2!$B$5)+(AK27*Sheet2!$B$6)+(AM27*Sheet2!$B$7)+(AN27*Sheet2!$B$8) -> 56.079386
A28: 21 | B28: G5 | C28: 3 | D28: Air Force | E28: 4 | F28: Troy Calhoun | G28: 19 | H28: 19 | I28: 135 | J28: 89 | K28: 135 | L28: 89 | M28: 1 | N28: 19 | O28: =N28+M28 -> 20 | P28: 2 | Q28: 0 | R28: 0 | S28: 0 | T28: 0 | U28: 13 | V28: 8 | W28: 1 | AC28: =I28/(SUM(I28:J28)) -> 0.60267857 | AD28: =IF($E28=1,AC28-0.1436,IF($E28=2,AC28-0.0718,IF($E28 = 3,AC28,IF($E28=4,AC28+0.0718, IF($E28=5,AC28+0.1436))))) -> 0.67447857 | AE28: =AD28+(0.0129*H28) -> 0.91957857 | AF28: =IF(C28=1,AE28-0.0145,IF(C28=2,AE28,IF(C28=3,AE28+0.0145))) -> 0.93407857 | AG28: =K28/(SUM(K28:L28)) -> 0.60267857 | AH28: =M28/(SUM(M28:N28)) -> 0.05 | AI28: =AH28+(0.0132*M28) -> 0.0632 | AJ28: =SUM(M28:N28)/SUM(K28:L28) -> 0.089285714 | AK28: =P28/G28 -> 0.10526316 | AL28: =V28/U28 -> 0.61538462 | AM28: =U28/G28 -> 0.68421053 | AN28: =W28/G28 -> 0.052631579 | AO28: =M28/K28 -> 0.0074074074 | AP28: =(AF28*Sheet2!$B$2)+(AG28*Sheet2!$B$3)+(AI28*Sheet2!$B$4)+(AJ28*Sheet2!$B$5)+(AK28*Sheet2!$B$6)+(AM28*Sheet2!$B$7)+(AN28*Sheet2!$B$8) -> 54.429073
A29: 22 | B29: ACC | C29: 2 | D29: Louisville | E29: 2 | F29: Brohm, Jeff | G29: 12 | H29: 3 | I29: 19 | J29: 8 | K29: 85 | L29: 52 | M29: 11 | N29: 12 | O29: =N29+M29 -> 23 | P29: 4 | Q29: 2 | R29: 0 | S29: 0 | T29: 0 | U29: 8 | V29: 6 | W29: 0 | AC29: =I29/(SUM(I29:J29)) -> 0.7037037 | AD29: =IF($E29=1,AC29-0.1436,IF($E29=2,AC29-0.0718,IF($E29 = 3,AC29,IF($E29=4,AC29+0.0718, IF($E29=5,AC29+0.1436))))) -> 0.6319037 | AE29: =AD29+(0.0129*H29) -> 0.6706037 | AF29: =IF(C29=1,AE29-0.0145,IF(C29=2,AE29,IF(C29=3,AE29+0.0145))) -> 0.6706037 | AG29: =K29/(SUM(K29:L29)) -> 0.62043796 | AH29: =M29/(SUM(M29:N29)) -> 0.47826087 | AI29: =AH29+(0.0132*M29) -> 0.62346087 | AJ29: =SUM(M29:N29)/SUM(K29:L29) -> 0.16788321 | AK29: =P29/G29 -> 0.33333333 | AL29: =V29/U29 -> 0.75 | AM29: =U29/G29 -> 0.66666667 | AN29: =W29/G29 -> 0 | AO29: =M29/K29 -> 0.12941176 | AP29: =(AF29*Sheet2!$B$2)+(AG29*Sheet2!$B$3)+(AI29*Sheet2!$B$4)+(AJ29*Sheet2!$B$5)+(AK29*Sheet2!$B$6)+(AM29*Sheet2!$B$7)+(AN29*Sheet2!$B$8) -> 53.79333
A30: 23 | B30: SEC | C30: 1 | D30: LSU | E30: 1 | F30: Brian Kelly | G30: 35 | H30: 4 | I30: 29 | J30: 11 | K30: 292 | L30: 107 | M30: 35 | N30: 37 | O30: =N30+M30 -> 72 | P30: 1 | Q30: 0 | R30: 0 | S30: 0 | T30: 0 | U30: 16 | V30: 10 | W30: 4 | AC30: =I30/(SUM(I30:J30)) -> 0.725 | AD30: =IF($E30=1,AC30-0.1436,IF($E30=2,AC30-0.0718,IF($E30 = 3,AC30,IF($E30=4,AC30+0.0718, IF($E30=5,AC30+0.1436))))) -> 0.5814 | AE30: =AD30+(0.0129*H30) -> 0.633 | AF30: =IF(C30=1,AE30-0.0145,IF(C30=2,AE30,IF(C30=3,AE30+0.0145))) -> 0.6185 | AG30: =K30/(SUM(K30:L30)) -> 0.73182957 | AH30: =M30/(SUM(M30:N30)) -> 0.48611111 | AI30: =AH30+(0.0132*M30) -> 0.94811111 | AJ30: =SUM(M30:N30)/SUM(K30:L30) -> 0.18045113 | AK30: =P30/G30 -> 0.028571429 | AL30: =V30/U30 -> 0.625 | AM30: =U30/G30 -> 0.45714286 | AN30: =W30/G30 -> 0.11428571 | AO30: =M30/K30 -> 0.11986301 | AP30: =(AF30*Sheet2!$B$2)+(AG30*Sheet2!$B$3)+(AI30*Sheet2!$B$4)+(AJ30*Sheet2!$B$5)+(AK30*Sheet2!$B$6)+(AM30*Sheet2!$B$7)+(AN30*Sheet2!$B$8) -> 52.998285
A31: 24 | B31: B12 | C31: 2 | D31: BYU | E31: 3 | F31: Kalani Sitake | G31: 10 | H31: 10 | I31: 72 | J31: 43 | K31: 72 | L31: 43 | M31: 8 | N31: 11 | O31: =N31+M31 -> 19 | P31: 0 | Q31: 0 | R31: 0 | S31: 0 | T31: 0 | U31: 7 | V31: 5 | W31: 0 | AC31: =I31/(SUM(I31:J31)) -> 0.62608696 | AD31: =IF($E31=1,AC31-0.1436,IF($E31=2,AC31-0.0718,IF($E31 = 3,AC31,IF($E31=4,AC31+0.0718, IF($E31=5,AC31+0.1436))))) -> 0.62608696 | AE31: =AD31+(0.0129*H31) -> 0.75508696 | AF31: =IF(C31=1,AE31-0.0145,IF(C31=2,AE31,IF(C31=3,AE31+0.0145))) -> 0.75508696 | AG31: =K31/(SUM(K31:L31)) -> 0.62608696 | AH31: =M31/(SUM(M31:N31)) -> 0.42105263 | AI31: =AH31+(0.0132*M31) -> 0.52665263 | AJ31: =SUM(M31:N31)/SUM(K31:L31) -> 0.16521739 | AK31: =P31/G31 -> 0 | AL31: =V31/U31 -> 0.71428571 | AM31: =U31/G31 -> 0.7 | AN31: =W31/G31 -> 0 | AO31: =M31/K31 -> 0.11111111 | AP31: =(AF31*Sheet2!$B$2)+(AG31*Sheet2!$B$3)+(AI31*Sheet2!$B$4)+(AJ31*Sheet2!$B$5)+(AK31*Sheet2!$B$6)+(AM31*Sheet2!$B$7)+(AN31*Sheet2!$B$8) -> 52.868483
... A41: 34 | B41: ACC | C41: 2 | D41: FSU | E41: 2 | F41: Norvell, Mike | G41: 10 | H41: 6 | I41: 33 | J41: 27 | K41: 71 | L41: 42 | M41: 8 | N41: 16 | O41: =N41+M41 -> 24 | P41: 4 | Q41: 2 | R41: 0 | S41: 0 | T41: 0 | U41: 5 | V41: 1 | W41: 4 | AC41: =I41/(SUM(I41:J41)) -> 0.55 | AD41: =IF($E41=1,AC41-0.1436,IF($E41=2,AC41-0.0718,IF($E41 = 3,AC41,IF($E41=4,AC41+0.0718, IF($E41=5,AC41+0.1436))))) -> 0.4782 | AE41: =AD41+(0.0129*H41) -> 0.5556 | AF41: =IF(C41=1,AE41-0.0145,IF(C41=2,AE41,IF(C41=3,AE41+0.0145))) -> 0.5556 | AG41: =K41/(SUM(K41:L41)) -> 0.62831858 | AH41: =M41/(SUM(M41:N41)) -> 0.33333333 | AI41: =AH41+(0.0132*M41) -> 0.43893333 | AJ41: =SUM(M41:N41)/SUM(K41:L41) -> 0.21238938 | AK41: =P41/G41 -> 0.4 | AL41: =V41/U41 -> 0.2 | AM41: =U41/G41 -> 0.5 | AN41: =W41/G41 -> 0.4 | AO41: =M41/K41 -> 0.11267606 | AP41: =(AF41*Sheet2!$B$2)+(AG41*Sheet2!$B$3)+(AI41*Sheet2!$B$4)+(AJ41*Sheet2!$B$5)+(AK41*Sheet2!$B$6)+(AM41*Sheet2!$B$7)+(AN41*Sheet2!$B$8) -> 49.525599
A42: 35 | B42: B12 | C42: 2 | D42: TCU | E42: 3 | F42: Sonny Dykes | G42: 16 | H42: 4 | I42: 27 | J42: 13 | K42: 98 | L42: 76 | M42: 11 | N42: 32 | O42: =N42+M42 -> 43 | P42: 2 | Q42: 1 | R42: 1 | S42: 1 | T42: 0 | U42: 7 | V42: 3 | W42: 2 | X42: 0 | Y42: 6 | AC42: =I42/(SUM(I42:J42)) -> 0.675 | AD42: =IF($E42=1,AC42-0.1436,IF($E42=2,AC42-0.0718,IF($E42 = 3,AC42,IF($E42=4,AC42+0.0718, IF($E42=5,AC42+0.1436))))) -> 0.675 | AE42: =AD42+(0.0129*H42) -> 0.7266 | AF42: =IF(C42=1,AE42-0.0145,IF(C42=2,AE42,IF(C42=3,AE42+0.0145))) -> 0.7266 | AG42: =K42/(SUM(K42:L42)) -> 0.56321839 | AH42: =M42/(SUM(M42:N42)) -> 0.25581395 | AI42: =AH42+(0.0132*M42) -> 0.40101395 | AJ42: =SUM(M42:N42)/SUM(K42:L42) -> 0.24712644 | AK42: =P42/G42 -> 0.125 | AL42: =V42/U42 -> 0.42857143 | AM42: =U42/G42 -> 0.4375 | AN42: =W42/G42 -> 0.125 | AO42: =M42/K42 -> 0.1122449 | AP42: =(AF42*Sheet2!$B$2)+(AG42*Sheet2!$B$3)+(AI42*Sheet2!$B$4)+(AJ42*Sheet2!$B$5)+(AK42*Sheet2!$B$6)+(AM42*Sheet2!$B$7)+(AN42*Sheet2!$B$8) -> 49.426772
A43: 36 | B43: B12 | C43: 2 | D43: Texas Tech | E43: 3 | F43: Joey McGuire | G43: 4 | H43: 4 | I43: 23 | J43: 16 | K43: 23 | L43: 16 | M43: 4 | N43: 7 | O43: =N43+M43 -> 11 | P43: 0 | Q43: 0 | R43: 0 | S43: 0 | T43: 0 | U43: 3 | V43: 2 | W43: 0 | X43: 0 | Y43: 1 | AC43: =I43/(SUM(I43:J43)) -> 0.58974359 | AD43: =IF($E43=1,AC43-0.1436,IF($E43=2,AC43-0.0718,IF($E43 = 3,AC43,IF($E43=4,AC43+0.0718, IF($E43=5,AC43+0.1436))))) -> 0.58974359 | AE43: =AD43+(0.0129*H43) -> 0.64134359 | AF43: =IF(C43=1,AE43-0.0145,IF(C43=2,AE43,IF(C43=3,AE43+0.0145))) -> 0.64134359 | AG43: =K43/(SUM(K43:L43)) -> 0.58974359 | AH43: =M43/(SUM(M43:N43)) -> 0.36363636 | AI43: =AH43+(0.0132*M43) -> 0.41643636 | AJ43: =SUM(M43:N43)/SUM(K43:L43) -> 0.28205128 | AK43: =P43/G43 -> 0 | AL43: =V43/U43 -> 0.66666667 | AM43: =U43/G43 -> 0.75 | AN43: =W43/G43 -> 0 | AO43: =M43/K43 -> 0.17391304 | AP43: =(AF43*Sheet2!$B$2)+(AG43*Sheet2!$B$3)+(AI43*Sheet2!$B$4)+(AJ43*Sheet2!$B$5)+(AK43*Sheet2!$B$6)+(AM43*Sheet2!$B$7)+(AN43*Sheet2!$B$8) -> 48.726774
A44: 37 | B44: ACC | C44: 2 | D44: Georgia Tech | E44: 3 | F44: Key, Brent | G44: 3 | H44: 3 | I44: 18 | J44: 16 | K44: 18 | L44: 16 | M44: 6 | N44: 1 | O44: =N44+M44 -> 7 | P44: 0 | Q44: 0 | R44: 0 | S44: 0 | T44: 0 | U44: 2 | V44: 1 | W44: 0 | AC44: =I44/(SUM(I44:J44)) -> 0.52941176 | AD44: =IF($E44=1,AC44-0.1436,IF($E44=2,AC44-0.0718,IF($E44 = 3,AC44,IF($E44=4,AC44+0.0718, IF($E44=5,AC44+0.1436))))) -> 0.52941176 | AE44: =AD44+(0.0129*H44) -> 0.56811176 | AF44: =IF(C44=1,AE44-0.0145,IF(C44=2,AE44,IF(C44=3,AE44+0.0145))) -> 0.56811176 | AG44: =K44/(SUM(K44:L44)) -> 0.52941176 | AH44: =M44/(SUM(M44:N44)) -> 0.85714286 | AI44: =AH44+(0.0132*M44) -> 0.93634286 | AJ44: =SUM(M44:N44)/SUM(K44:L44) -> 0.20588235 | AK44: =P44/G44 -> 0 | AL44: =V44/U44 -> 0.5 | AM44: =U44/G44 -> 0.66666667 | AN44: =W44/G44 -> 0 | AO44: =M44/K44 -> 0.33333333 | AP44: =(AF44*Sheet2!$B$2)+(AG44*Sheet2!$B$3)+(AI44*Sheet2!$B$4)+(AJ44*Sheet2!$B$5)+(AK44*Sheet2!$B$6)+(AM44*Sheet2!$B$7)+(AN44*Sheet2!$B$8) -> 48.561066
A45: 38 | B45: BIG10 | C45: 1 | D45: Illinois | E45: 2 | F45: Bret Bielema | G45: 17 | H45: 5 | I45: 28 | J45: 22 | K45: 125 | L45: 80 | M45: 22 | N45: 42 | O45: =N45+M45 -> 64 | P45: 2 | Q45: 3 | R45: 0 | S45: 0 | T45: 0 | U45: 11 | V45: 5 | W45: 1 | AC45: =I45/(SUM(I45:J45)) -> 0.56 | AD45: =IF($E45=1,AC45-0.1436,IF($E45=2,AC45-0.0718,IF($E45 = 3,AC45,IF($E45=4,AC45+0.0718, IF($E45=5,AC45+0.1436))))) -> 0.4882 | AE45: =AD45+(0.0129*H45) -> 0.5527 | AF45: =IF(C45=1,AE45-0.0145,IF(C45=2,AE45,IF(C45=3,AE45+0.0145))) -> 0.5382 | AG45: =K45/(SUM(K45:L45)) -> 0.6097561 | AH45: =M45/(SUM(M45:N45)) -> 0.34375 | AI45: =AH45+(0.0132*M45) -> 0.63415 | AJ45: =SUM(M45:N45)/SUM(K45:L45) -> 0.31219512 | AK45: =P45/G45 -> 0.11764706 | AL45: =V45/U45 -> 0.45454545 | AM45: =U45/G45 -> 0.64705882 | AN45: =W45/G45 -> 0.058823529 | AO45: =M45/K45 -> 0.176 | AP45: =(AF45*Sheet2!$B$2)+(AG45*Sheet2!$B$3)+(AI45*Sheet2!$B$4)+(AJ45*Sheet2!$B$5)+(AK45*Sheet2!$B$6)+(AM45*Sheet2!$B$7)+(AN45*Sheet2!$B$8) -> 48.43675
A46: 39 | B46: SEC | C46: 1 | D46: Ole Miss | E46: 2 | F46: Lane Kiffin | G46: 14 | H46: 6 | I46: 44 | J46: 18 | K46: 105 | L46: 52 | M46: 3 | N46: 15 | O46: =N46+M46 -> 18 | P46: 2 | Q46: 2 | R46: 0 | S46: 0 | T46: 0 | U46: 8 | V46: 4 | W46: 0 | AC46: =I46/(SUM(I46:J46)) -> 0.70967742 | AD46: =IF($E46=1,AC46-0.1436,IF($E46=2,AC46-0.0718,IF($E46 = 3,AC46,IF($E46=4,AC46+0.0718, IF($E46=5,AC46+0.1436))))) -> 0.63787742 | AE46: =AD46+(0.0129*H46) -> 0.71527742 | AF46: =IF(C46=1,AE46-0.0145,IF(C46=2,AE46,IF(C46=3,AE46+0.0145))) -> 0.70077742 | AG46: =K46/(SUM(K46:L46)) -> 0.66878981 | AH46: =M46/(SUM(M46:N46)) -> 0.16666667 | AI46: =AH46+(0.0132*M46) -> 0.20626667 | AJ46: =SUM(M46:N46)/SUM(K46:L46) -> 0.11464968 | AK46: =P46/G46 -> 0.14285714 | AL46: =V46/U46 -> 0.5 | AM46: =U46/G46 -> 0.57142857 | AN46: =W46/G46 -> 0 | AO46: =M46/K46 -> 0.028571429 | AP46: =(AF46*Sheet2!$B$2)+(AG46*Sheet2!$B$3)+(AI46*Sheet2!$B$4)+(AJ46*Sheet2!$B$5)+(AK46*Sheet2!$B$6)+(AM46*Sheet2!$B$7)+(AN46*Sheet2!$B$8) -> 48.255026
A47: 40 | B47: B12 | C47: 2 | D47: ASU | E47: 3 | F47: Kenny Dillingham | G47: 3 | H47: 3 | I47: 14 | J47: 12 | K47: 14 | L47: 12 | M47: 4 | N47: 6 | O47: =N47+M47 -> 10 | P47: 1 | Q47: 1 | R47: 1 | S47: 0 | T47: 0 | U47: 1 | V47: 0 | W47: 1 | AC47: =I47/(SUM(I47:J47)) -> 0.53846154 | AD47: =IF($E47=1,AC47-0.1436,IF($E47=2,AC47-0.0718,IF($E47 = 3,AC47,IF($E47=4,AC47+0.0718, IF($E47=5,AC47+0.1436))))) -> 0.53846154 | AE47: =AD47+(0.0129*H47) -> 0.57716154 | AF47: =IF(C47=1,AE47-0.0145,IF(C47=2,AE47,IF(C47=3,AE47+0.0145))) -> 0.57716154 | AG47: =K47/(SUM(K47:L47)) -> 0.53846154 | AH47: =M47/(SUM(M47:N47)) -> 0.4 | AI47: =AH47+(0.0132*M47) -> 0.4528 | AJ47: =SUM(M47:N47)/SUM(K47:L47) -> 0.38461538 | AK47: =P47/G47 -> 0.33333333 | AL47: =V47/U47 -> 0 | AM47: =U47/G47 -> 0.33333333 | AN47: =W47/G47 -> 0.33333333 | AO47: =M47/K47 -> 0.28571429 | AP47: =(AF47*Sheet2!$B$2)+(AG47*Sheet2!$B$3)+(AI47*Sheet2!$B$4)+(AJ47*Sheet2!$B$5)+(AK47*Sheet2!$B$6)+(AM47*Sheet2!$B$7)+(AN47*Sheet2!$B$8) -> 47.677372
A48: 41 | B48: SEC | C48: 1 | D48: Missouri | E48: 3 | F48: Eli Drinkwitz | G48: 7 | H48: 6 | I48: 38 | J48: 24 | K48: 50 | L48: 25 | M48: 1 | N48: 7 | O48: =N48+M48 -> 8 | P48: 1 | Q48: 1 | R48: 0 | S48: 0 | T48: 0 | U48: 4 | V48: 2 | W48: 1 | AC48: =I48/(SUM(I48:J48)) -> 0.61290323 | AD48: =IF($E48=1,AC48-0.1436,IF($E48=2,AC48-0.0718,IF($E48 = 3,AC48,IF($E48=4,AC48+0.0718, IF($E48=5,AC48+0.1436))))) -> 0.61290323 | AE48: =AD48+(0.0129*H48) -> 0.69030323 | AF48: =IF(C48=1,AE48-0.0145,IF(C48=2,AE48,IF(C48=3,AE48+0.0145))) -> 0.67580323 | AG48: =K48/(SUM(K48:L48)) -> 0.66666667 | AH48: =M48/(SUM(M48:N48)) -> 0.125 | AI48: =AH48+(0.0132*M48) -> 0.1382 | AJ48: =SUM(M48:N48)/SUM(K48:L48) -> 0.10666667 | AK48: =P48/G48 -> 0.14285714 | AL48: =V48/U48 -> 0.5 | AM48: =U48/G48 -> 0.57142857 | AN48: =W48/G48 -> 0.14285714 | AO48: =M48/K48 -> 0.02 | AP48: =(AF48*Sheet2!$B$2)+(AG48*Sheet2!$B$3)+(AI48*Sheet2!$B$4)+(AJ48*Sheet2!$B$5)+(AK48*Sheet2!$B$6)+(AM48*Sheet2!$B$7)+(AN48*Sheet2!$B$8) -> 47.292256
A49: 42 | B49: SEC | C49: 1 | D49: South Carolina | E49: 2 | F49: Shane Beamer | G49: 5 | H49: 5 | I49: 29 | J49: 22 | K49: 29 | L49: 22 | M49: 6 | N49: 12 | O49: =N49+M49 -> 18 | P49: 0 | Q49: 0 | R49: 0 | S49: 0 | T49: 0 | U49: 3 | V49: 1 | W49: 3 | AC49: =I49/(SUM(I49:J49)) -> 0.56862745 | AD49: =IF($E49=1,AC49-0.1436,IF($E49=2,AC49-0.0718,IF($E49 = 3,AC49,IF($E49=4,AC49+0.0718, IF($E49=5,AC49+0.1436))))) -> 0.49682745 | AE49: =AD49+(0.0129*H49) -> 0.56132745 | AF49: =IF(C49=1,AE49-0.0145,IF(C49=2,AE49,IF(C49=3,AE49+0.0145))) -> 0.54682745 | AG49: =K49/(SUM(K49:L49)) -> 0.56862745 | AH49: =M49/(SUM(M49:N49)) -> 0.33333333 | AI49: =AH49+(0.0132*M49) -> 0.41253333 | AJ49: =SUM(M49:N49)/SUM(K49:L49) -> 0.35294118 | AK49: =P49/G49 -> 0 | AL49: =V49/U49 -> 0.33333333 | AM49: =U49/G49 -> 0.6 | AN49: =W49/G49 -> 0.6 | AO49: =M49/K49 -> 0.20689655 | AP49: =(AF49*Sheet2!$B$2)+(AG49*Sheet2!$B$3)+(AI49*Sheet2!$B$4)+(AJ49*Sheet2!$B$5)+(AK49*Sheet2!$B$6)+(AM49*Sheet2!$B$7)+(AN49*Sheet2!$B$8) -> 47.166255
...

Sheet Sheet2
A1: Metric | B1: Weight
A2: Adj Win % based on Conference Ranking | B2: 35
A3: Total Win % | B3: 20
A4: Adj T25 win % | B4: 10
A5: T25 Games/Total Games (Record Strength) | B5: 10
A6: Conference Champ Apps/yr | B6: 10
A7: Bowl Appearances per Season | B7: 10
A8: Awards/year | B8: 5
A9: TOTAL | B9: =SUM(B2:B8) -> 100
